<?xml version="1.0" encoding="utf-8"?>
<!-- This URDF was automatically created by SolidWorks to URDF Exporter! Originally created by
Stephen Brawner (brawner@gmail.com) 
     Commit Version: 1.6.0-4-g7f85cfe  Build Version: 1.6.7995.38578
     For more information, please see http://wiki.ros.org/sw_urdf_exporter -->
<robot name="keti_robot_description">
	<link name="world" />
	<joint name="world_base" type="fixed">
		<origin xyz="0 0 0.803" rpy="0 0 0" />
		<parent link="world" />
		<child link="base_link" />
		<axis xyz="0 0 0" />
	</joint>
	<link name="base">
		<inertial>
			<origin xyz="-3.0420543732843E-06 -0.000310266853479853 0.472198524600166" rpy="0 0 0" />
			<mass value="856.710523085829" />
			<inertia ixx="56.4891846636914" ixy="3.15004799218073E-07" ixz="-4.10579819989819E-05"
				iyy="76.5651533017626" iyz="3.71330417890454E-05" izz="70.8459779417847" />
		</inertial>
		<visual>
			<origin xyz="0 0 0" rpy="0 0 0" />
			<geometry>
				<mesh filename="package://keti_robot_description/meshes/base_link.STL" />
			</geometry>
			<material name="">
				<color rgba="0.792156862745098 0.819607843137255 0.933333333333333 1" />
			</material>
		</visual>
		<collision>
			<origin xyz="0 0 0" rpy="0 0 0" />
			<geometry>
				<mesh filename="package://keti_robot_description/meshes/base_link.STL" />
			</geometry>
		</collision>
	</link>
	<link name="base_link">
		<inertial>
			<origin xyz="-3.33346887438442E-05 0.000285564928122946 0.0441636819540465" rpy="0 0 0" />
			<mass value="2.2652251953819" />
			<inertia ixx="0.00613758696409751" ixy="5.04787655447911E-06"
				ixz="-2.06360462586892E-06" iyy="0.00606962711919972" iyz="-2.85582975739181E-06"
				izz="0.00867794435574655" />
		</inertial>
		<visual>
			<origin xyz="0 0 0" rpy="0 0 0" />
			<geometry>
				<mesh filename="package://keti_robot_description/meshes/base.STL" />
			</geometry>
			<material name="">
				<color rgba="0.594117647058824 0.594117647058824 0.594117647058824 1" />
			</material>
		</visual>
		<collision>
			<origin xyz="0 0 0" rpy="0 0 0" />
			<geometry>
				<mesh filename="package://keti_robot_description/meshes/base.STL" />
			</geometry>
		</collision>
	</link>
	<joint name="base_fixed" type="fixed">
		<origin xyz="0 0 -0.803" rpy="0 0 0" />
		<parent link="base_link" />
		<child link="base" />
		<axis xyz="0 0 0" />
	</joint>
	<link name="link1">
		<inertial>
			<origin xyz="-0.000152782130418023 -0.0118929965334738 0.185272104905482" rpy="0 0 0" />
			<mass value="3.38760416330855" />
			<inertia ixx="0.00965857274328299" ixy="2.63774902696517E-06"
				ixz="-2.20411506005037E-06" iyy="0.0100366373115559" iyz="0.00227418354706203"
				izz="0.00982041012260562" />
		</inertial>
		<visual>
			<origin xyz="0 0 0" rpy="0 0 0" />
			<geometry>
				<mesh filename="package://keti_robot_description/meshes/link1.STL" />
			</geometry>
			<material name="">
				<color rgba="0.294117647058824 0.294117647058824 0.294117647058824 1" />
			</material>
		</visual>
		<collision>
			<origin xyz="0 0 0" rpy="0 0 0" />
			<geometry>
				<mesh filename="package://keti_robot_description/meshes/link1.STL" />
			</geometry>
		</collision>
	</link>
	<joint name="q1" type="revolute">
		<origin xyz="0 0 0" rpy="0 0 -1.5708" />
		<parent link="base_link" />
		<child link="link1" />
		<axis xyz="0 0 1" />
		<limit lower="-6.28" upper="6.28" effort="100" velocity="10" />
	</joint>
	<link name="link2">
		<inertial>
			<origin xyz="0.256519293636053 -5.02230044113333E-05 -0.182156904780236" rpy="0 0 0" />
			<mass value="10.3582396210808" />
			<inertia ixx="0.0227209214296945" ixy="-2.60074287292687E-06" ixz="0.00160304095858948"
				iyy="0.120603244564478" iyz="2.02017347940835E-06" izz="0.120795201071467" />
		</inertial>
		<visual>
			<origin xyz="0 0 0" rpy="0 0 0" />
			<geometry>
				<mesh filename="package://keti_robot_description/meshes/link2.STL" />
			</geometry>
			<material name="">
				<color rgba="0.294117647058824 0.294117647058824 0.294117647058824 1" />
			</material>
		</visual>
		<collision>
			<origin xyz="0 0 0" rpy="0 0 0" />
			<geometry>
				<mesh filename="package://keti_robot_description/meshes/link2.STL" />
			</geometry>
		</collision>
	</link>
	<joint name="q2" type="revolute">
		<origin xyz="0 0 0.197" rpy="1.5708 -1.5708 3.1416" />
		<parent link="link1" />
		<child link="link2" />
		<axis xyz="0 0 1" />
		<limit lower="-6.28" upper="6.28" effort="100" velocity="10" />
	</joint>
	<link name="link3">
		<inertial>
			<origin xyz="0.267192004078909 5.52341009596446E-08 0.143134757572694" rpy="0 0 0" />
			<mass value="5.05188870959058" />
			<inertia ixx="0.00628405006865319" ixy="-2.80291262476242E-10"
				ixz="-0.000370506230492888" iyy="0.0617515944810592" iyz="-5.4630264122874E-09"
				izz="0.0618261271509705" />
		</inertial>
		<visual>
			<origin xyz="0 0 0" rpy="0 0 0" />
			<geometry>
				<mesh filename="package://keti_robot_description/meshes/link3.STL" />
			</geometry>
			<material name="">
				<color rgba="0.294117647058824 0.294117647058824 0.294117647058824 1" />
			</material>
		</visual>
		<collision>
			<origin xyz="0 0 0" rpy="0 0 0" />
			<geometry>
				<mesh filename="package://keti_robot_description/meshes/link3.STL" />
			</geometry>
		</collision>
	</link>
	<joint name="q3" type="revolute">
		<origin xyz="0.6127 0 -0.1875" rpy="0 0 1.5708" />
		<parent link="link2" />
		<child link="link3" />
		<axis xyz="0 0 1" />
		<limit lower="-6.28" upper="6.28" effort="100" velocity="10" />
	</joint>
	<link name="link4">
		<inertial>
			<origin xyz="0.00636955026235164 4.99285552901796E-08 -0.111895613258826" rpy="0 0 0" />
			<mass value="0.80963566860197" />
			<inertia ixx="0.000814578063119343" ixy="-1.64833595815118E-08"
				ixz="0.000215197469116586" iyy="0.000838074727071174" iyz="-7.69664931217343E-09"
				izz="0.000873078218716129" />
		</inertial>
		<visual>
			<origin xyz="0 0 0" rpy="0 0 0" />
			<geometry>
				<mesh filename="package://keti_robot_description/meshes/link4.STL" />
			</geometry>
			<material name="">
				<color rgba="0.294117647058824 0.294117647058824 0.294117647058824 1" />
			</material>
		</visual>
		<collision>
			<origin xyz="0 0 0" rpy="0 0 0" />
			<geometry>
				<mesh filename="package://keti_robot_description/meshes/link4.STL" />
			</geometry>
		</collision>
	</link>
	<joint name="q4" type="revolute">
		<origin xyz="0.57015 0 0.1484" rpy="0 0 0" />
		<parent link="link3" />
		<child link="link4" />
		<axis xyz="0 0 1" />
		<limit lower="-6.28" upper="6.28" effort="100" velocity="10" />
	</joint>
	<link name="link5">
		<inertial>
			<origin xyz="-2.42105024084172E-06 -0.00725433397814212 0.111976976596473" rpy="0 0 0" />
			<mass value="0.822358205233283" />
			<inertia ixx="0.000866980211698627" ixy="-1.08075544041225E-08"
				ixz="-3.98724334907599E-09" iyy="0.000830295979143927" iyz="0.000222525041768018"
				izz="0.000899390558482124" />
		</inertial>
		<visual>
			<origin xyz="0 0 0" rpy="0 0 0" />
			<geometry>
				<mesh filename="package://keti_robot_description/meshes/link5.STL" />
			</geometry>
			<material name="">
				<color rgba="0.294117647058824 0.294117647058824 0.294117647058824 1" />
			</material>
		</visual>
		<collision>
			<origin xyz="0 0 0" rpy="0 0 0" />
			<geometry>
				<mesh filename="package://keti_robot_description/meshes/link5.STL" />
			</geometry>
		</collision>
	</link>
	<joint name="q5" type="revolute">
		<origin xyz="0 0 -0.11715" rpy="0 -1.5708 -3.1416" />
		<parent link="link4" />
		<child link="link5" />
		<axis xyz="0 0 1" />
		<limit lower="-6.28" upper="6.28" effort="100" velocity="10" />
	</joint>
	<link name="link6">
		<inertial>
			<origin xyz="-0.000244083935800887 -6.91008968434215E-07 -0.092173017250227" rpy="0 0 0" />
			<mass value="0.228532944621864" />
			<inertia ixx="0.000139960650226687" ixy="-2.60711970230224E-10"
				ixz="5.76979086366175E-07" iyy="0.000137593815442646" iyz="-1.40521694254523E-10"
				izz="0.000218309631187425" />
		</inertial>
		<visual>
			<origin xyz="0 0 0" rpy="0 0 0" />
			<geometry>
				<mesh filename="package://keti_robot_description/meshes/link6.STL" />
			</geometry>
			<material name="">
				<color rgba="0.294117647058824 0.294117647058824 0.294117647058824 1" />
			</material>
		</visual>
		<collision>
			<origin xyz="0 0 0" rpy="0 0 0" />
			<geometry>
				<mesh filename="package://keti_robot_description/meshes/link6.STL" />
			</geometry>
		</collision>
	</link>
	<joint name="q6" type="revolute">
		<origin xyz="0 0 0.11715" rpy="1.5708 -1.5708 -3.1416" />
		<parent link="link5" />
		<child link="link6" />
		<axis xyz="0 0 1" />
		<limit lower="-6.28" upper="6.28" effort="100" velocity="10" />
	</joint>
	<link name="gripper_cam_jig">
		<inertial>
			<origin xyz="-0.010218584080396 0.000257415782811576 -0.0363863576584786" rpy="0 0 0" />
			<mass value="0.363809799934884" />
			<inertia ixx="0.000158886140435799" ixy="-8.85041552125519E-07"
				ixz="-1.54307287779922E-06" iyy="0.000125067393480588" iyz="4.49899048463505E-08"
				izz="0.000214360238843583" />
		</inertial>
		<visual>
			<origin xyz="0 0 0" rpy="0 0 0" />
			<geometry>
				<mesh filename="package://keti_robot_description/meshes/gripper_cam_jig.STL" />
			</geometry>
			<material name="">
				<color rgba="0.898039215686275 0.917647058823529 0.929411764705882 1" />
			</material>
		</visual>
		<collision>
			<origin xyz="0 0 0" rpy="0 0 0" />
			<geometry>
				<mesh filename="package://keti_robot_description/meshes/gripper_cam_jig.STL" />
			</geometry>
		</collision>
	</link>
	<joint name="link6_jig" type="fixed">
		<origin xyz="0 0 -0.1183" rpy="0 0 2.4958" />
		<parent link="link6" />
		<child link="gripper_cam_jig" />
		<axis xyz="0 0 0" />
	</joint>
	<link name="cam">
		<inertial>
			<origin xyz="0.00221623043115715 -0.000129869319643316 0.0106603028259826" rpy="0 0 0" />
			<mass value="0.0326887265041798" />
			<inertia ixx="1.99509746764601E-06" ixy="-3.91609962559602E-09"
				ixz="4.07029726642134E-08" iyy="2.02605334751521E-05" iyz="-1.17619372131272E-08"
				izz="2.15265481774982E-05" />
		</inertial>
		<visual>
			<origin xyz="0 0 0" rpy="0 0 0" />
			<geometry>
				<mesh filename="package://keti_robot_description/meshes/cam.STL" />
			</geometry>
			<material name="">
				<color rgba="0.792156862745098 0.819607843137255 0.933333333333333 1" />
			</material>
		</visual>
		<collision>
			<origin xyz="0 0 0" rpy="0 0 0" />
			<geometry>
				<mesh filename="package://keti_robot_description/meshes/cam.STL" />
			</geometry>
		</collision>
	</link>
	<joint name="jig_cam" type="fixed">
		<origin xyz="-0.0583225279657438 0 -0.0820000000000001"
			rpy="3.14159265358979 0 1.5707963267949" />
		<parent link="gripper_cam_jig" />
		<child link="cam" />
		<axis xyz="0 0 0" />
	</joint>
	<link name="gripper">
		<inertial>
			<origin xyz="-0.000298406473471236 -0.00150550427302965 -0.0219098918209939" rpy="0 0 0" />
			<mass value="0.353450939027098" />
			<inertia ixx="0.000535578621167894" ixy="-7.44147202172271E-07"
				ixz="-7.1670590855247E-08" iyy="0.000164985101936106" iyz="4.50332236529226E-07"
				izz="0.000594983187518549" />
		</inertial>
		<visual>
			<origin xyz="0 0 0" rpy="0 0 0" />
			<geometry>
				<mesh filename="package://keti_robot_description/meshes/gripper.STL" />
			</geometry>
			<material name="">
				<color rgba="0.752941176470588 0.752941176470588 0.752941176470588 1" />
			</material>
		</visual>
		<collision>
			<origin xyz="0 0 0" rpy="0 0 0" />
			<geometry>
				<mesh filename="package://keti_robot_description/meshes/gripper.STL" />
			</geometry>
		</collision>
	</link>
	<joint name="jig_gripper" type="fixed">
		<origin xyz="0 0 -0.0658" rpy="0 0 0" />
		<parent link="gripper_cam_jig" />
		<child link="gripper" />
		<axis xyz="0 0 0" />
	</joint>
	<link name="tooltip1">
		<inertial>
			<origin xyz="-0.00674255822092196 -0.000133093696191855 -0.00876783058720992"
				rpy="0 0 0" />
			<mass value="0.0737973344451048" />
			<inertia ixx="6.48942548977301E-06" ixy="3.76635397579075E-08"
				ixz="1.31847470029505E-06" iyy="2.76299349617891E-05" iyz="-9.29189992090126E-08"
				izz="2.88157641063004E-05" />
		</inertial>
		<visual>
			<origin xyz="0 0 0" rpy="0 0 0" />
			<geometry>
				<mesh filename="package://keti_robot_description/meshes/tooltip1.STL" />
			</geometry>
			<material name="">
				<color rgba="0.650980392156863 0.619607843137255 0.588235294117647 1" />
			</material>
		</visual>
		<collision>
			<origin xyz="0 0 0" rpy="0 0 0" />
			<geometry>
				<mesh filename="package://keti_robot_description/meshes/tooltip1.STL" />
			</geometry>
		</collision>
	</link>
	<joint name="s1" type="prismatic">
		<origin xyz="0 0.041 -0.0608" rpy="1.5708 -1.5708 0" />
		<parent link="gripper" />
		<child link="tooltip1" />
		<axis xyz="0 0 1" />
		<limit lower="0" upper="0.04" effort="100" velocity="10" />
	</joint>
	<link name="tooltip2">
		<inertial>
			<origin xyz="-0.00674255822092173 -0.000133093696191633 -0.00876783058720987"
				rpy="0 0 0" />
			<mass value="0.0737973344451051" />
			<inertia ixx="6.48942548977302E-06" ixy="3.76635397578962E-08"
				ixz="1.31847470029503E-06" iyy="2.76299349617893E-05" iyz="-9.29189992090066E-08"
				izz="2.88157641063006E-05" />
		</inertial>
		<visual>
			<origin xyz="0 0 0" rpy="0 0 0" />
			<geometry>
				<mesh filename="package://keti_robot_description/meshes/tooltip2.STL" />
			</geometry>
			<material name="">
				<color rgba="0.650980392156863 0.619607843137255 0.588235294117647 1" />
			</material>
		</visual>
		<collision>
			<origin xyz="0 0 0" rpy="0 0 0" />
			<geometry>
				<mesh filename="package://keti_robot_description/meshes/tooltip2.STL" />
			</geometry>
		</collision>
	</link>
	<joint name="s2" type="prismatic">
		<origin xyz="0 -0.041 -0.0608" rpy="-1.5708 -1.5708 0" />
		<parent link="gripper" />
		<child link="tooltip2" />
		<axis xyz="0 0 1" />
		<limit lower="0" upper="0.04" effort="100" velocity="10" />
	</joint>
	<link name="end" />
	<joint name="link6_end" type="fixed">
		<origin xyz="0 0 -0.1153" rpy="1.5708 0 1.5708" />
		<parent link="link6" />
		<child link="end" />
		<axis xyz="0 0 0" />
	</joint>
	<link name="table">
		<inertial>
			<origin xyz="0.0032093 -0.0086466 0.55421" rpy="0 0 0" />
			<mass value="54.316" />
			<inertia ixx="1.8674" ixy="1.7462E-05" ixz="0.0040242"
				iyy="1.9466" iyz="0.0058242" izz="3.4226" />
		</inertial>
		<visual>
			<origin xyz="0 0 0" rpy="0 0 0" />
			<geometry>
				<mesh filename="package://keti_robot_description/meshes/table.STL" />
			</geometry>
			<material name="">
				<color rgba="0.89804 0.91765 0.92941 1" />
			</material>
		</visual>
		<collision>
			<origin xyz="0 0 0" rpy="0 0 0" />
			<geometry>
				<mesh filename="package://keti_robot_description/meshes/table.STL" />
			</geometry>
		</collision>
	</link>
	<joint name="base_table" type="fixed">
		<origin xyz="-0.018106 -0.73131 0.017" rpy="0 0 -2.1411E-05" />
		<parent link="base" />
		<child link="table" />
		<axis xyz="0 0 0" />
	</joint>
	<link name="cage">
		<inertial>
			<origin xyz="0.018106 -0.019568 0.71077" rpy="0 0 0" />
			<mass value="48.96" />
			<inertia ixx="2.056" ixy="-1.0608E-05" ixz="1.2319E-11"
				iyy="2.5515" iyz="2.4847E-17" izz="2.2932" />
		</inertial>
		<visual>
			<origin xyz="0 0 0" rpy="0 0 0" />
			<geometry>
				<mesh filename="package://keti_robot_description/meshes/cage.STL" />
			</geometry>
			<material name="">
				<color rgba="0.50196 0.50196 0.50196 1" />
			</material>
		</visual>
		<collision>
			<origin xyz="0 0 0" rpy="0 0 0" />
			<geometry>
				<mesh filename="package://keti_robot_description/meshes/cage.STL" />
			</geometry>
		</collision>
	</link>
	<joint name="table_cage" type="fixed">
		<origin xyz="0 0 0.803" rpy="0 0 0" />
		<parent link="table" />
		<child link="cage" />
		<axis xyz="0 0 0" />
	</joint>

	<link name="sample_box">
		<inertial>
			<origin xyz="0.0 0.0 0.04294" rpy="0 0 0"/>
			<mass value="3.96050"/>
			<inertia ixx="0.10637" ixy="0.0" ixz="0.0"
				iyy="0.05286" iyz="0.0" izz="0.13493"/>
		</inertial>
		<visual>
			<origin xyz="0 0 0" rpy="0 0 0"/>
			<geometry>
				<mesh filename="package://keti_robot_description/meshes/sample_box.STL"/>
			</geometry>
			<material name="">
				<color rgba="0.580392156 0.580392156 0.0 1"/>
			</material>
		</visual>
		<collision>
			<origin xyz="0 0 0" rpy="0 0 0" />
			<geometry>
				<mesh filename="package://keti_robot_description/meshes/sample_box.STL" />
			</geometry>
		</collision>
	</link>
	<joint name="cage_box" type="fixed">
		<origin xyz="0.21961 0.01 0" rpy="0 0 0"/>
		<parent link="cage"/>
		<child link="sample_box"/>
		<axis xyz="0 0 0"/>
	</joint>
	<link name="sample">
		<inertial>
			<origin xyz="-0.02906 0.01418 0.00939"/>
			<mass value="0.21697"/>
			<inertia ixx="0.00173" ixy="-0.00010" ixz="0.00007"
				iyy="0.00210" iyz="0.00002" izz="0.00053"/>
		</inertial>
		<visual>
			<origin xyz="0 0 0" rpy="0 0 0"/>
			<geometry>
				<mesh filename="package://keti_robot_description/meshes/sample.STL"/>
			</geometry>
			<material name="">
				<color rgba="0.509803 0.509803 0.509803 1"/>
			</material>
		</visual>
		<collision>
			<origin xyz="0 0 0" rpy="0 0 0" />
			<geometry>
				<mesh filename="package://keti_robot_description/meshes/sample.STL" />
			</geometry>
		</collision>
	</link>
	<joint name="box_sample" type="fixed">
		<origin xyz="0.03961 0.04829 0.010" rpy="1.5708 0 0"/>
		<parent link="sample_box"/>
		<child link="sample"/>
		<axis xyz="0 0 0"/>
	</joint>
	<link name="guide_plate">
		<inertial>
			<origin xyz="0.0 0.009 0.0" rpy="0 0 0"/>
			<mass value="2.83099"/>
			<inertia ixx="0.04799" ixy="0.0" ixz="0.0"
				iyy="0.07653" iyz="0.0" izz="0.02914"/>
		</inertial>
		<visual>
			<origin xyz="0 0 0" rpy="0 0 0"/>
			<geometry>
				<mesh filename="package://keti_robot_description/meshes/guide_plate.STL"/>
			</geometry>
			<material name="">
				<color rgba="0.4980392 0.4980392 1.0 1"/>
			</material>
		</visual>
		<collision>
			<origin xyz="0 0 0" rpy="0 0 0" />
			<geometry>
				<mesh filename="package://keti_robot_description/meshes/guide_plate.STL" />
			</geometry>
		</collision>
	</link>
	<joint name="cage_plate" type="fixed">
		<origin xyz="-0.18189 0.025 0" rpy="1.5708 0 0"/>
		<parent link="cage"/>
		<child link="guide_plate"/>
		<axis xyz="0 0 0"/>
	</joint>
	<link name="guide">
		<inertial>
			<origin xyz="-0.03871 0.01388 0.05706" rpy="0 0 0"/>
			<mass value="0.78172"/>
			<inertia ixx="0.01274" ixy="-0.00101" ixz="-0.00389"
				iyy="0.01991" iyz="0.00123" izz="0.00813"/>
		</inertial>
		<visual>
			<origin xyz="0 0 0" rpy="0 0 0"/>
			<geometry>
				<mesh filename="package://keti_robot_description/meshes/guide.STL"/>
			</geometry>
			<material name="">
				<color rgba="0.580392156 0.580392156 0.580392156 1"/>
			</material>
		</visual>
		<collision>
			<origin xyz="0 0 0" rpy="0 0 0" />
			<geometry>
				<mesh filename="package://keti_robot_description/meshes/guide.STL" />
			</geometry>
		</collision>
	</link>
	<joint name="plate_guide" type="fixed">
		<origin xyz="0.01888 0.018 -0.02292" rpy="0 0 0"/>
		<parent link="guide_plate"/>
		<child link="guide"/>
		<axis xyz="0 0 0"/>
	</joint>

	<transmission name="trans_q1">
		<type>transmission_interface/SimpleTransmission</type>
		<joint name="q1">
			<hardwareInterface>hardware_interface/PositionJointInterface</hardwareInterface>
		</joint>
		<actuator name="q1_motor">
			<hardwareInterface>hardware_interface/PositionJointInterface</hardwareInterface>
			<mechanicalReduction>1</mechanicalReduction>
		</actuator>
	</transmission>
	<transmission name="trans_q2">
		<type>transmission_interface/SimpleTransmission</type>
		<joint name="q2">
			<hardwareInterface>hardware_interface/PositionJointInterface</hardwareInterface>
		</joint>
		<actuator name="q2_motor">
			<hardwareInterface>hardware_interface/PositionJointInterface</hardwareInterface>
			<mechanicalReduction>1</mechanicalReduction>
		</actuator>
	</transmission>
	<transmission name="trans_q3">
		<type>transmission_interface/SimpleTransmission</type>
		<joint name="q3">
			<hardwareInterface>hardware_interface/PositionJointInterface</hardwareInterface>
		</joint>
		<actuator name="q3_motor">
			<hardwareInterface>hardware_interface/PositionJointInterface</hardwareInterface>
			<mechanicalReduction>1</mechanicalReduction>
		</actuator>
	</transmission>
	<transmission name="trans_q4">
		<type>transmission_interface/SimpleTransmission</type>
		<joint name="q4">
			<hardwareInterface>hardware_interface/PositionJointInterface</hardwareInterface>
		</joint>
		<actuator name="q4_motor">
			<hardwareInterface>hardware_interface/PositionJointInterface</hardwareInterface>
			<mechanicalReduction>1</mechanicalReduction>
		</actuator>
	</transmission>
	<transmission name="trans_q5">
		<type>transmission_interface/SimpleTransmission</type>
		<joint name="q5">
			<hardwareInterface>hardware_interface/PositionJointInterface</hardwareInterface>
		</joint>
		<actuator name="q5_motor">
			<hardwareInterface>hardware_interface/PositionJointInterface</hardwareInterface>
			<mechanicalReduction>1</mechanicalReduction>
		</actuator>
	</transmission>
	<transmission name="trans_q6">
		<type>transmission_interface/SimpleTransmission</type>
		<joint name="q6">
			<hardwareInterface>hardware_interface/PositionJointInterface</hardwareInterface>
		</joint>
		<actuator name="q6_motor">
			<hardwareInterface>hardware_interface/PositionJointInterface</hardwareInterface>
			<mechanicalReduction>1</mechanicalReduction>
		</actuator>
	</transmission>
	<transmission name="trans_s1">
		<type>transmission_interface/SimpleTransmission</type>
		<joint name="s1">
			<hardwareInterface>hardware_interface/PositionJointInterface</hardwareInterface>
		</joint>
		<actuator name="s1_motor">
			<hardwareInterface>hardware_interface/PositionJointInterface</hardwareInterface>
			<mechanicalReduction>1</mechanicalReduction>
		</actuator>
	</transmission>
	<transmission name="trans_s2">
		<type>transmission_interface/SimpleTransmission</type>
		<joint name="s2">
			<hardwareInterface>hardware_interface/PositionJointInterface</hardwareInterface>
		</joint>
		<actuator name="s2_motor">
			<hardwareInterface>hardware_interface/PositionJointInterface</hardwareInterface>
			<mechanicalReduction>1</mechanicalReduction>
		</actuator>
	</transmission>
	<gazebo>
		<plugin name="gazebo_ros_control" filename="libgazebo_ros_control.so">
			<robotNamespace>/</robotNamespace>
		</plugin>
	</gazebo>

	<link name="cam_optical" />
	<joint name="cam_joint" type="fixed">
		<origin xyz="0 0 0.02495" rpy="-1.5708 -1.5708 0" />
		<parent link="cam" />
		<child link="cam_optical" />
		<axis xyz="0 0 0" />
	</joint>
	<gazebo reference="cam_optical">
		<sensor type="camera" name="Realsense">
			<always_on>true</always_on>
			<visualize>true</visualize>
			<camera>
				<horizontal_fov>1.085595</horizontal_fov>
				<image>
					<width>640</width>
					<height>480</height>
					<format>R8G8B8</format>
				</image>
				<clip>
					<near>0.01</near>
					<far>100</far>
				</clip>
			</camera>
			<plugin name="camera_controller" filename="libgazebo_ros_camera.so">
				<alwaysOn>true</alwaysOn>
				<updateRate>30.0</updateRate>
				<cameraName>camera</cameraName>
				<frameName>cam_optical</frameName>
				<imageTopicName>rgb/image_raw</imageTopicName>
				<cameraInfoTopicName>rgb/camera_info</cameraInfoTopicName>
				<hackBaselink>0.07</hackBaselink>
				<distortionK1>0.0</distortionK1>
				<distortionK2>0.0</distortionK2>
				<distortionK3>0.0</distortionK3>
				<distortionT1>0.0</distortionT1>
				<distortionT2>0.0</distortionT2>
			</plugin>
		</sensor>
	</gazebo>

	<gazebo reference="cage">
		<material>Gazebo/GreyTransparent</material>
	</gazebo>
	<gazebo reference="guide">
		<material>Gazebo/Gray</material>
	</gazebo>
	<gazebo reference="guide_plate">
		<material>Gazebo/BlueTransparent</material>
	</gazebo>
	<gazebo reference="sample_box">
		<material>Gazebo/DarkYellow</material>
	</gazebo>
	<gazebo reference="sample">
		<material>Gazebo/Gray</material>
	</gazebo>

</robot>