<?xml version="1.0" encoding="utf-8"?>
<!-- This URDF was automatically created by SolidWorks to URDF Exporter! Originally created by Stephen Brawner (brawner@gmail.com) 
     Commit Version: 1.6.0-4-g7f85cfe  Build Version: 1.6.7995.38578
     For more information, please see http://wiki.ros.org/sw_urdf_exporter -->
<robot
  name="keti_robot_arm">
  <link
    name="base_link">
    <inertial>
      <origin
        xyz="-3.36084696400674E-05 0.00028713387556778 0.0438378186374772"
        rpy="0 0 0" />
      <mass
        value="2.25213983841171" />
      <inertia
        ixx="0.00610179267270193"
        ixy="5.05489700638155E-06"
        ixz="-2.06579420136556E-06"
        iyy="0.00603383828429949"
        iyz="-2.85750001496908E-06"
        izz="0.00860649294977137" />
    </inertial>
    <visual>
      <origin
        xyz="0 0 0"
        rpy="0 0 0" />
      <geometry>
        <mesh
          filename="package://keti_robot_description/meshes/base_link.STL" />
      </geometry>
      <material
        name="">
        <color
          rgba="0.8 0.8 0.8 1" />
      </material>
    </visual>
    <collision>
      <origin
        xyz="0 0 0"
        rpy="0 0 0" />
      <geometry>
        <mesh
          filename="package://keti_robot_description/meshes/base_link.STL" />
      </geometry>
    </collision>
  </link>
  <link
    name="link1">
    <inertial>
      <origin
        xyz="-0.000155596593394897 -0.0115300991030924 0.185903011387218"
        rpy="0 0 0" />
      <mass
        value="3.38716123949166" />
      <inertia
        ixx="0.00965712344078406"
        ixy="2.56321142215039E-06"
        ixz="-2.07213259316219E-06"
        iyy="0.00999757711288239"
        iyz="0.00227412846191921"
        izz="0.00985394828837277" />
    </inertial>
    <visual>
      <origin
        xyz="0 0 0"
        rpy="0 0 0" />
      <geometry>
        <mesh
          filename="package://keti_robot_description/meshes/link1.STL" />
      </geometry>
      <material
        name="">
        <color
          rgba="0.792156862745098 0.819607843137255 0.933333333333333 1" />
      </material>
    </visual>
    <collision>
      <origin
        xyz="0 0 0"
        rpy="0 0 0" />
      <geometry>
        <mesh
          filename="package://keti_robot_description/meshes/link1.STL" />
      </geometry>
    </collision>
  </link>
  <joint
    name="q1"
    type="revolute">
    <origin
      xyz="0 0 0"
      rpy="0 0 0" />
    <parent
      link="base_link" />
    <child
      link="link1" />
    <axis
      xyz="0 0 1" />
    <limit
      lower="-6.3"
      upper="6.3"
      effort="10"
      velocity="100" />
  </joint>
  <link
    name="link2">
    <inertial>
      <origin
        xyz="-5.04047652291201E-05 -0.255908501214572 -0.182094524542086"
        rpy="0 0 0" />
      <mass
        value="10.3635885023069" />
      <inertia
        ixx="0.120627099316039"
        ixy="2.65066669408744E-06"
        ixz="2.16897828737298E-06"
        iyy="0.0227437773556374"
        iyz="-0.0016029791309899"
        izz="0.120841683724806" />
    </inertial>
    <visual>
      <origin
        xyz="0 0 0"
        rpy="0 0 0" />
      <geometry>
        <mesh
          filename="package://keti_robot_description/meshes/link2.STL" />
      </geometry>
      <material
        name="">
        <color
          rgba="0.294117647058824 0.294117647058824 0.294117647058824 1" />
      </material>
    </visual>
    <collision>
      <origin
        xyz="0 0 0"
        rpy="0 0 0" />
      <geometry>
        <mesh
          filename="package://keti_robot_description/meshes/link2.STL" />
      </geometry>
    </collision>
  </link>
  <joint
    name="q2"
    type="revolute">
    <origin
      xyz="0 0 0.198"
      rpy="-1.5708 0 0" />
    <parent
      link="link1" />
    <child
      link="link2" />
    <axis
      xyz="0 0 1" />
    <limit
      lower="-6.3"
      upper="6.3"
      effort="10"
      velocity="100" />
  </joint>
  <link
    name="link3">
    <inertial>
      <origin
        xyz="0.266215180264014 1.29712622268241E-07 0.143135404945513"
        rpy="0 0 0" />
      <mass
        value="5.05083741641896" />
      <inertia
        ixx="0.00628902623789062"
        ixy="9.1337717733775E-09"
        ixz="-0.000370519945348952"
        iyy="0.061756757690725"
        iyz="-1.56347717729795E-09"
        izz="0.0618362170084191" />
    </inertial>
    <visual>
      <origin
        xyz="0 0 0"
        rpy="0 0 0" />
      <geometry>
        <mesh
          filename="package://keti_robot_description/meshes/link3.STL" />
      </geometry>
      <material
        name="">
        <color
          rgba="0.294117647058824 0.294117647058824 0.294117647058824 1" />
      </material>
    </visual>
    <collision>
      <origin
        xyz="0 0 0"
        rpy="0 0 0" />
      <geometry>
        <mesh
          filename="package://keti_robot_description/meshes/link3.STL" />
      </geometry>
    </collision>
  </link>
  <joint
    name="q3"
    type="revolute">
    <origin
      xyz="0 -0.6127 -0.1875"
      rpy="0 0 -1.5708" />
    <parent
      link="link2" />
    <child
      link="link3" />
    <axis
      xyz="0 0 1" />
    <limit
      lower="-6.3"
      upper="6.3"
      effort="10"
      velocity="100" />
  </joint>
  <link
    name="link4">
    <inertial>
      <origin
        xyz="0.00564731690989118 -2.03600273793181E-07 -0.111294177443476"
        rpy="0 0 0" />
      <mass
        value="0.809634247265308" />
      <inertia
        ixx="0.000806283674225212"
        ixy="-1.71998154303632E-08"
        ixz="0.000215199499704635"
        iyy="0.000838076862135837"
        iyz="-7.62439682589746E-09"
        izz="0.00088136714943862" />
    </inertial>
    <visual>
      <origin
        xyz="0 0 0"
        rpy="0 0 0" />
      <geometry>
        <mesh
          filename="package://keti_robot_description/meshes/link4.STL" />
      </geometry>
      <material
        name="">
        <color
          rgba="0.792156862745098 0.819607843137255 0.933333333333333 1" />
      </material>
    </visual>
    <collision>
      <origin
        xyz="0 0 0"
        rpy="0 0 0" />
      <geometry>
        <mesh
          filename="package://keti_robot_description/meshes/link4.STL" />
      </geometry>
    </collision>
  </link>
  <joint
    name="q4"
    type="revolute">
    <origin
      xyz="0.57015 0 0.1484"
      rpy="0 0 0" />
    <parent
      link="link3" />
    <child
      link="link4" />
    <axis
      xyz="0 0 1" />
    <limit
      lower="-6.3"
      upper="6.3"
      effort="10"
      velocity="100" />
  </joint>
  <link
    name="link5">
    <inertial>
      <origin
        xyz="3.79221289037446E-07 -0.0065154111458714 0.111384778201544"
        rpy="0 0 0" />
      <mass
        value="0.822358399005338" />
      <inertia
        ixx="0.00086697648332544"
        ixy="-4.3209208438896E-09"
        ixz="-3.43499554605311E-09"
        iyy="0.00082200885145279"
        iyz="0.000222523008866456"
        izz="0.000907682647219081" />
    </inertial>
    <visual>
      <origin
        xyz="0 0 0"
        rpy="0 0 0" />
      <geometry>
        <mesh
          filename="package://keti_robot_description/meshes/link5.STL" />
      </geometry>
      <material
        name="">
        <color
          rgba="0.792156862745098 0.819607843137255 0.933333333333333 1" />
      </material>
    </visual>
    <collision>
      <origin
        xyz="0 0 0"
        rpy="0 0 0" />
      <geometry>
        <mesh
          filename="package://keti_robot_description/meshes/link5.STL" />
      </geometry>
    </collision>
  </link>
  <joint
    name="q5"
    type="revolute">
    <origin
      xyz="0 0 -0.11715"
      rpy="1.5708 0 1.5708" />
    <parent
      link="link4" />
    <child
      link="link5" />
    <axis
      xyz="0 0 1" />
    <limit
      lower="-6.3"
      upper="6.3"
      effort="10"
      velocity="100" />
  </joint>
  <link
    name="link6">
    <inertial>
      <origin
        xyz="-2.74288486201701E-07 -0.000235269428608742 -0.0906803365828259"
        rpy="0 0 0" />
      <mass
        value="0.237678022472349" />
      <inertia
        ixx="0.000145950216129124"
        ixy="-1.23036106344042E-09"
        ixz="-7.04161447052051E-10"
        iyy="0.000148314461323765"
        iyz="5.7765854614293E-07"
        izz="0.000234953691644831" />
    </inertial>
    <visual>
      <origin
        xyz="0 0 0"
        rpy="0 0 0" />
      <geometry>
        <mesh
          filename="package://keti_robot_description/meshes/link6.STL" />
      </geometry>
      <material
        name="">
        <color
          rgba="0.792156862745098 0.819607843137255 0.933333333333333 1" />
      </material>
    </visual>
    <collision>
      <origin
        xyz="0 0 0"
        rpy="0 0 0" />
      <geometry>
        <mesh
          filename="package://keti_robot_description/meshes/link6.STL" />
      </geometry>
    </collision>
  </link>
  <joint
    name="q6"
    type="revolute">
    <origin
      xyz="0 0 0.11715"
      rpy="-1.5708 0 0" />
    <parent
      link="link5" />
    <child
      link="link6" />
    <axis
      xyz="0 0 1" />
    <limit
      lower="-6.3"
      upper="6.3"
      effort="10"
      velocity="100" />
  </joint>
  <link
    name="gripper_body">
    <inertial>
      <origin
        xyz="-3.45920909952668E-05 -0.0477817173459312 -0.00571131983067263"
        rpy="0 0 0" />
      <mass
        value="0.933264814357233" />
      <inertia
        ixx="0.000450791407921585"
        ixy="4.50924518749628E-07"
        ixz="-7.44739815604934E-07"
        iyy="0.00142129108945366"
        iyz="-3.93915847422977E-06"
        izz="0.00128066984792434" />
    </inertial>
    <visual>
      <origin
        xyz="0 0 0"
        rpy="0 0 0" />
      <geometry>
        <mesh
          filename="package://keti_robot_description/meshes/gripper_body.STL" />
      </geometry>
      <material
        name="">
        <color
          rgba="0.898039215686275 0.917647058823529 0.929411764705882 1" />
      </material>
    </visual>
    <collision>
      <origin
        xyz="0 0 0"
        rpy="0 0 0" />
      <geometry>
        <mesh
          filename="package://keti_robot_description/meshes/gripper_body.STL" />
      </geometry>
    </collision>
  </link>
  <joint
    name="link6_gripper_fixed"
    type="fixed">
    <origin
      xyz="0 0 -0.1148"
      rpy="1.5708 0 0" />
    <parent
      link="link6" />
    <child
      link="gripper_body" />
    <axis
      xyz="0 0 0" />
  </joint>
  <link
    name="gripper_tool1">
    <inertial>
      <origin
        xyz="-0.0503901981194649 -0.00839540838169439 -0.000187095087317068"
        rpy="0 0 0" />
      <mass
        value="0.0524980209707729" />
      <inertia
        ixx="4.96961994940061E-06"
        ixy="9.16328438600949E-07"
        ixz="-9.29191075202697E-08"
        iyy="5.26806301784339E-06"
        iyz="3.76648518766332E-08"
        izz="4.33143562379133E-06" />
    </inertial>
    <visual>
      <origin
        xyz="0 0 0"
        rpy="0 0 0" />
      <geometry>
        <mesh
          filename="package://keti_robot_description/meshes/gripper_tool1.STL" />
      </geometry>
      <material
        name="">
        <color
          rgba="0.650980392156863 0.619607843137255 0.588235294117647 1" />
      </material>
    </visual>
    <collision>
      <origin
        xyz="0 0 0"
        rpy="0 0 0" />
      <geometry>
        <mesh
          filename="package://keti_robot_description/meshes/gripper_tool1.STL" />
      </geometry>
    </collision>
  </link>
  <joint
    name="s1"
    type="prismatic">
    <origin
      xyz="0 -0.0962 0"
      rpy="0 0 0" />
    <parent
      link="gripper_body" />
    <child
      link="gripper_tool1" />
    <axis
      xyz="1 0 0" />
    <limit
      lower="0"
      upper="0.04"
      effort="10"
      velocity="100" />
  </joint>
  <link
    name="gripper_finger1">
    <inertial>
      <origin
        xyz="-0.047830477436016 -0.0616732966021152 -4.02028360380058E-07"
        rpy="0 0 0" />
      <mass
        value="0.0233180451311379" />
      <inertia
        ixx="2.40087905135542E-05"
        ixy="3.97733646582783E-07"
        ixz="-1.76194958848478E-12"
        iyy="1.26145385442102E-06"
        iyz="-3.65200575464404E-11"
        izz="2.34253553003692E-05" />
    </inertial>
    <visual>
      <origin
        xyz="0 0 0"
        rpy="0 0 0" />
      <geometry>
        <mesh
          filename="package://keti_robot_description/meshes/gripper_finger1.STL" />
      </geometry>
      <material
        name="">
        <color
          rgba="0.792156862745098 0.819607843137255 0.933333333333333 1" />
      </material>
    </visual>
    <collision>
      <origin
        xyz="0 0 0"
        rpy="0 0 0" />
      <geometry>
        <mesh
          filename="package://keti_robot_description/meshes/gripper_finger1.STL" />
      </geometry>
    </collision>
  </link>
  <joint
    name="tool_finger1_fixed"
    type="fixed">
    <origin
      xyz="0 0 0"
      rpy="0 0 0" />
    <parent
      link="gripper_tool1" />
    <child
      link="gripper_finger1" />
    <axis
      xyz="0 0 0" />
  </joint>
  <link
    name="gripper_tool2">
    <inertial>
      <origin
        xyz="0.050390198119466 -0.00839540838169439 0.000187095087317957"
        rpy="0 0 0" />
      <mass
        value="0.052498020970773" />
      <inertia
        ixx="4.96961994940061E-06"
        ixy="-9.1632843860095E-07"
        ixz="-9.29191075202696E-08"
        iyy="5.2680630178434E-06"
        iyz="-3.76648518766344E-08"
        izz="4.33143562379133E-06" />
    </inertial>
    <visual>
      <origin
        xyz="0 0 0"
        rpy="0 0 0" />
      <geometry>
        <mesh
          filename="package://keti_robot_description/meshes/gripper_tool2.STL" />
      </geometry>
      <material
        name="">
        <color
          rgba="0.650980392156863 0.619607843137255 0.588235294117647 1" />
      </material>
    </visual>
    <collision>
      <origin
        xyz="0 0 0"
        rpy="0 0 0" />
      <geometry>
        <mesh
          filename="package://keti_robot_description/meshes/gripper_tool2.STL" />
      </geometry>
    </collision>
  </link>
  <joint
    name="s2"
    type="prismatic">
    <origin
      xyz="0 -0.0962 0"
      rpy="0 0 0" />
    <parent
      link="gripper_body" />
    <child
      link="gripper_tool2" />
    <axis
      xyz="-1 0 0" />
    <limit
      lower="0"
      upper="0.04"
      effort="10"
      velocity="100" />
  </joint>
  <link
    name="gripper_finger2">
    <inertial>
      <origin
        xyz="0.0478304774360172 -0.0616732966021147 4.02028361046192E-07"
        rpy="0 0 0" />
      <mass
        value="0.023318045131138" />
      <inertia
        ixx="2.40087905135545E-05"
        ixy="-3.97733646582811E-07"
        ixz="-1.7619495854565E-12"
        iyy="1.26145385442102E-06"
        iyz="3.6520057602396E-11"
        izz="2.34253553003694E-05" />
    </inertial>
    <visual>
      <origin
        xyz="0 0 0"
        rpy="0 0 0" />
      <geometry>
        <mesh
          filename="package://keti_robot_description/meshes/gripper_finger2.STL" />
      </geometry>
      <material
        name="">
        <color
          rgba="0.792156862745098 0.819607843137255 0.933333333333333 1" />
      </material>
    </visual>
    <collision>
      <origin
        xyz="0 0 0"
        rpy="0 0 0" />
      <geometry>
        <mesh
          filename="package://keti_robot_description/meshes/gripper_finger2.STL" />
      </geometry>
    </collision>
  </link>
  <joint
    name="tool_finger2_fixed"
    type="fixed">
    <origin
      xyz="0 0 0"
      rpy="0 0 0" />
    <parent
      link="gripper_tool2" />
    <child
      link="gripper_finger2" />
    <axis
      xyz="0 0 0" />
  </joint>
  <link
    name="cam">
    <inertial>
      <origin
        xyz="0.0014399625101349 -5.94806382812063E-05 -0.0144824351521329"
        rpy="0 0 0" />
      <mass
        value="0.0224324424296924" />
      <inertia
        ixx="1.5561270767764E-06"
        ixy="-1.37007630764484E-09"
        ixz="1.48641223628634E-07"
        iyy="1.39866481202687E-05"
        iyz="-2.3852444733374E-09"
        izz="1.4977644157627E-05" />
    </inertial>
    <visual>
      <origin
        xyz="0 0 0"
        rpy="0 0 0" />
      <geometry>
        <mesh
          filename="package://keti_robot_description/meshes/cam.STL" />
      </geometry>
      <material
        name="">
        <color
          rgba="0.792156862745098 0.819607843137255 0.933333333333333 1" />
      </material>
    </visual>
    <collision>
      <origin
        xyz="0 0 0"
        rpy="0 0 0" />
      <geometry>
        <mesh
          filename="package://keti_robot_description/meshes/cam.STL" />
      </geometry>
    </collision>
  </link>
  <joint
    name="gripper_cam_fixed"
    type="fixed">
    <origin
      xyz="0 -0.13845 -0.0685"
      rpy="1.5708 0 0" />
    <parent
      link="gripper_body" />
    <child
      link="cam" />
    <axis
      xyz="0 0 0" />
  </joint>
  <link
    name="base">
    <inertial>
      <origin
        xyz="-1.28688321068826E-06 0.000310942291804728 -0.323288844730514"
        rpy="0 0 0" />
      <mass
        value="838.015231637391" />
      <inertia
        ixx="54.3575108059622"
        ixy="-3.81584107573326E-15"
        ixz="6.11415690387546E-16"
        iyy="74.0754281872674"
        iyz="6.12342523382769E-17"
        izz="69.561169810993" />
    </inertial>
    <visual>
      <origin
        xyz="0 0 0"
        rpy="0 0 0" />
      <geometry>
        <mesh
          filename="package://keti_robot_description/meshes/base.STL" />
      </geometry>
      <material
        name="">
        <color
          rgba="0.792156862745098 0.819607843137255 0.933333333333333 1" />
      </material>
    </visual>
    <collision>
      <origin
        xyz="0 0 0"
        rpy="0 0 0" />
      <geometry>
        <mesh
          filename="package://keti_robot_description/meshes/base.STL" />
      </geometry>
    </collision>
  </link>
  <joint
    name="base_fixed"
    type="fixed">
    <origin
      xyz="0 0 0"
      rpy="0 0 0" />
    <parent
      link="base_link" />
    <child
      link="base" />
    <axis
      xyz="0 0 0" />
  </joint>
  <link
    name="place">
    <inertial>
      <origin
        xyz="-0.210001286883211 -0.749689057708196 -0.0805000000000003"
        rpy="0 0 0" />
      <mass
        value="0.785447283360145" />
      <inertia
        ixx="0.0132205587747909"
        ixy="1.32472975100367E-18"
        ixz="2.03192199097574E-21"
        iyy="0.0080030601215886"
        iyz="6.46234853556509E-24"
        izz="0.0212203461993655" />
    </inertial>
    <visual>
      <origin
        xyz="0 0 0"
        rpy="0 0 0" />
      <geometry>
        <mesh
          filename="package://keti_robot_description/meshes/place.STL" />
      </geometry>
      <material
        name="">
        <color
          rgba="0.3 0.3 0.3 1" />
      </material>
    </visual>
    <collision>
      <origin
        xyz="0 0 0"
        rpy="0 0 0" />
      <geometry>
        <mesh
          filename="package://keti_robot_description/meshes/place.STL" />
      </geometry>
    </collision>
  </link>
  <joint
    name="base_plate_fixed"
    type="fixed">
    <origin
      xyz="0 0 0"
      rpy="0 0 0" />
    <parent
      link="base_link" />
    <child
      link="place" />
    <axis
      xyz="0 0 0" />
  </joint>
  <link
    name="place_cross">
    <inertial>
      <origin
        xyz="0 -2.22044604925031E-16 0.00632920795289479"
        rpy="0 0 0" />
      <mass
        value="0.0578280000000003" />
      <inertia
        ixx="3.42810502491726E-05"
        ixy="1.78360819581747E-21"
        ixz="3.18948076485842E-20"
        iyy="3.42810502491724E-05"
        iyz="9.25119797073764E-22"
        izz="6.63513947000005E-05" />
    </inertial>
    <visual>
      <origin
        xyz="0 0 0"
        rpy="0 0 0.52" />
      <geometry>
        <mesh
          filename="package://keti_robot_description/meshes/place_cross.STL" />
      </geometry>
      <material
        name="">
        <color
          rgba="0.1 0.1 0.933333333333333 1" />
      </material>
    </visual>
    <collision>
      <origin
        xyz="0 0 0"
        rpy="0 0 0" />
      <geometry>
        <mesh
          filename="package://keti_robot_description/meshes/place_cross.STL" />
      </geometry>
    </collision>
  </link>
  <joint
    name="place_cross_fixed"
    type="fixed">
    <origin
      xyz="-0.28511 -0.67677 -0.078"
      rpy="0 0 0" />
    <parent
      link="place" />
    <child
      link="place_cross" />
    <axis
      xyz="0 0 0" />
  </joint>
  <link
    name="place_circle">
    <inertial>
      <origin
        xyz="-1.38777878078145E-17 0 0.00633087207893085"
        rpy="0 0 0" />
      <mass
        value="0.0577456825709279" />
      <inertia
        ixx="3.50125843490266E-05"
        ixy="-1.75505226671088E-21"
        ixz="3.33474887313518E-20"
        iyy="3.50125843490264E-05"
        iyz="4.75888101417994E-22"
        izz="6.78100728333874E-05" />
    </inertial>
    <visual>
      <origin
        xyz="0 0 0"
        rpy="0 0 0" />
      <geometry>
        <mesh
          filename="package://keti_robot_description/meshes/place_circle.STL" />
      </geometry>
      <material
        name="">
        <color
          rgba="0.1 0.1 0.933333333333333 1" />
      </material>
    </visual>
    <collision>
      <origin
        xyz="0 0 0"
        rpy="0 0 0" />
      <geometry>
        <mesh
          filename="package://keti_robot_description/meshes/place_circle.STL" />
      </geometry>
    </collision>
  </link>
  <joint
    name="place_circle_rixed"
    type="fixed">
    <origin
      xyz="-0.16925 -0.84711 -0.078"
      rpy="0 0 0" />
    <parent
      link="place" />
    <child
      link="place_circle" />
    <axis
      xyz="0 0 0" />
  </joint>
  <link
    name="place_rectangle">
    <inertial>
      <origin
        xyz="6.93889390390723E-18 0 0.00492506066510467"
        rpy="0 0 0" />
      <mass
        value="0.0418280000000002" />
      <inertia
        ixx="2.51335188313047E-05"
        ixy="-4.78949338497427E-21"
        ixz="-3.67398477789802E-22"
        iyy="2.51335188313045E-05"
        iyz="-7.51373122444433E-22"
        izz="4.89191280333338E-05" />
    </inertial>
    <visual>
      <origin
        xyz="0 0 0"
        rpy="0 0 0.79" />
      <geometry>
        <mesh
          filename="package://keti_robot_description/meshes/place_rectangle.STL" />
      </geometry>
      <material
        name="">
        <color
          rgba="0.1 0.1 0.933333333333333 1" />
      </material>
    </visual>
    <collision>
      <origin
        xyz="0 0 0"
        rpy="0 0 0" />
      <geometry>
        <mesh
          filename="package://keti_robot_description/meshes/place_rectangle.STL" />
      </geometry>
    </collision>
  </link>
  <joint
    name="place_rectangle_fixed"
    type="fixed">
    <origin
      xyz="-0.15072 -0.71284 -0.078"
      rpy="0 0 0" />
    <parent
      link="place" />
    <child
      link="place_rectangle" />
    <axis
      xyz="0 0 0" />
  </joint>
  <link
    name="pick">
    <inertial>
      <origin
        xyz="0.204998713116789 -0.749689057708195 -0.0428648648648652"
        rpy="0 0 0" />
      <mass
        value="4.07592" />
      <inertia
        ixx="0.0979734755675673"
        ixy="-7.99274219726029E-18"
        ixz="-1.12613192894528E-18"
        iyy="0.0442374275675675"
        iyz="-1.73250152083534E-17"
        izz="0.13078746" />
    </inertial>
    <visual>
      <origin
        xyz="0 0 0"
        rpy="0 0 0" />
      <geometry>
        <mesh
          filename="package://keti_robot_description/meshes/pick.STL" />
      </geometry>
      <material
        name="">
        <color
          rgba="0.9 0.9 0.3 1" />
      </material>
    </visual>
    <collision>
      <origin
        xyz="0 0 0"
        rpy="0 0 0" />
      <geometry>
        <mesh
          filename="package://keti_robot_description/meshes/pick.STL" />
      </geometry>
    </collision>
  </link>
  <joint
    name="base_pick_fixed"
    type="fixed">
    <origin
      xyz="0 0 0"
      rpy="0 0 0" />
    <parent
      link="base_link" />
    <child
      link="pick" />
    <axis
      xyz="0 0 0" />
  </joint>
  <link
    name="pick_cross">
    <inertial>
      <origin
        xyz="0 0 0.01"
        rpy="0 0 0" />
      <mass
        value="0.0400000000000002" />
      <inertia
        ixx="9.06666666666675E-06"
        ixy="-1.97213547269696E-20"
        ixz="-6.47231336187252E-23"
        iyy="9.06666666666671E-06"
        iyz="-2.44695634235106E-22"
        izz="1.54666666666668E-05" />
    </inertial>
    <visual>
      <origin
        xyz="0 0 0"
        rpy="0 0 0" />
      <geometry>
        <mesh
          filename="package://keti_robot_description/meshes/pick_cross.STL" />
      </geometry>
      <material
        name="">
        <color
          rgba="0.792156862745098 0.819607843137255 0.933333333333333 1" />
      </material>
    </visual>
    <collision>
      <origin
        xyz="0 0 0"
        rpy="0 0 0" />
      <geometry>
        <mesh
          filename="package://keti_robot_description/meshes/pick_cross.STL" />
      </geometry>
    </collision>
  </link>
  <joint
    name="pick_cross_fixed"
    type="fixed">
    <origin
      xyz="0.16702 -0.80412 -0.068"
      rpy="0 0 0" />
    <parent
      link="pick" />
    <child
      link="pick_cross" />
    <axis
      xyz="0 0 0" />
  </joint>
  <link
    name="pick_circle">
    <inertial>
      <origin
        xyz="0 0 0.0100000000000001"
        rpy="0 0 0" />
      <mass
        value="0.0441236688196687" />
      <inertia
        ixx="9.21725056780871E-06"
        ixy="1.95876369052557E-21"
        ixz="2.10582221076763E-37"
        iyy="9.21725056780872E-06"
        iyz="1.41172157875717E-22"
        izz="1.54929232143062E-05" />
    </inertial>
    <visual>
      <origin
        xyz="0 0 0"
        rpy="0 0 0" />
      <geometry>
        <mesh
          filename="package://keti_robot_description/meshes/pick_circle.STL" />
      </geometry>
      <material
        name="">
        <color
          rgba="0.792156862745098 0.819607843137255 0.933333333333333 1" />
      </material>
    </visual>
    <collision>
      <origin
        xyz="0 0 0"
        rpy="0 0 0" />
      <geometry>
        <mesh
          filename="package://keti_robot_description/meshes/pick_circle.STL" />
      </geometry>
    </collision>
  </link>
  <joint
    name="pick_circle_fixed"
    type="fixed">
    <origin
      xyz="0.23709 -0.71828 -0.068"
      rpy="0 0 0" />
    <parent
      link="pick" />
    <child
      link="pick_circle" />
    <axis
      xyz="0 0 0" />
  </joint>
  <link
    name="pick_rectangle">
    <inertial>
      <origin
        xyz="5.55111512312578E-17 0 0.015"
        rpy="0 0 0" />
      <mass
        value="0.0442885009851994" />
      <inertia
        ixx="2.49543942403889E-05"
        ixy="-6.57608586979657E-20"
        ixz="-2.60137572529475E-22"
        iyy="2.49543942403888E-05"
        iyz="1.16380977668695E-21"
        izz="4.32655133329977E-05" />
    </inertial>
    <visual>
      <origin
        xyz="0 0 0"
        rpy="0 0 0" />
      <geometry>
        <mesh
          filename="package://keti_robot_description/meshes/pick_rectangle.STL" />
      </geometry>
      <material
        name="">
        <color
          rgba="0.792156862745098 0.819607843137255 0.933333333333333 1" />
      </material>
    </visual>
    <collision>
      <origin
        xyz="0 0 0"
        rpy="0 0 0" />
      <geometry>
        <mesh
          filename="package://keti_robot_description/meshes/pick_rectangle.STL" />
      </geometry>
    </collision>
  </link>
  <joint
    name="pick_rectangle_fixed"
    type="fixed">
    <origin
      xyz="0.16748 -0.60831 -0.068"
      rpy="0 0 0" />
    <parent
      link="pick" />
    <child
      link="pick_rectangle" />
    <axis
      xyz="0 0 0" />
  </joint>
  <link
    name="table">
    <inertial>
      <origin
        xyz="-1.28688321091031E-06 -0.724689057708195 -0.3655"
        rpy="0 0 0" />
      <mass
        value="361.6" />
      <inertia
        ixx="28.9046466666667"
        ixy="-2.16393591768236E-15"
        ixz="-1.46486195417846E-15"
        iyy="28.9046466666667"
        iyz="-1.48173644243146E-15"
        izz="38.5706666666667" />
    </inertial>
    <visual>
      <origin
        xyz="0 0 0"
        rpy="0 0 0" />
      <geometry>
        <mesh
          filename="package://keti_robot_description/meshes/table.STL" />
      </geometry>
      <material
        name="">
        <color
          rgba="0.792156862745098 0.819607843137255 0.933333333333333 1" />
      </material>
    </visual>
    <collision>
      <origin
        xyz="0 0 0"
        rpy="0 0 0" />
      <geometry>
        <mesh
          filename="package://keti_robot_description/meshes/table.STL" />
      </geometry>
    </collision>
  </link>
  <joint
    name="base_table_fixed"
    type="fixed">
    <origin
      xyz="0 0 0"
      rpy="0 0 0" />
    <parent
      link="base_link" />
    <child
      link="table" />
    <axis
      xyz="0 0 0" />
  </joint>


</robot>